DEBUG 2019-11-04 13:48:19.521 UTC: 	 Running on: Linux lxplus606.cern.ch 2.6.32-754.23.1.el6.x86_64 #1 SMP Thu Sep 26 11:57:28 CEST 2019 x86_64 x86_64 x86_64 GNU/Linux
Description:	Scientific Linux CERN SLC release 6.10 (Carbon)

DEBUG 2019-11-04 13:48:19.522 UTC: 	 Executing command: 'status'
DEBUG 2019-11-04 13:48:19.522 UTC: 	 Found CRAB cache file /afs/cern.ch/user/k/kaliyana/.crab3
ERROR 2019-11-04 13:48:19.523 UTC: 	 Error: crab_2018_MC is not a valid CRAB project directory.
ERROR 2019-11-04 13:48:19.523 UTC: 	 Caught exception
Traceback (most recent call last):
  File "/cvmfs/cms.cern.ch/crab3/slc6_amd64_gcc493/cms/crabclient/3.3.1910.patch2/bin/crab", line 160, in <module>
    client()
  File "/cvmfs/cms.cern.ch/crab3/slc6_amd64_gcc493/cms/crabclient/3.3.1910.patch2/bin/crab", line 145, in __call__
    self.cmd = sub_cmd(self.logger, args[1:])
  File "/cvmfs/cms.cern.ch/crab3/slc6_amd64_gcc493/cms/crabclient/3.3.1910.patch2/lib/python2.7/site-packages/CRABClient/Commands/status.py", line 40, in __init__
    SubCommand.__init__(self, logger, cmdargs)
  File "/cvmfs/cms.cern.ch/crab3/slc6_amd64_gcc493/cms/crabclient/3.3.1910.patch2/lib/python2.7/site-packages/CRABClient/Commands/SubCommand.py", line 262, in __init__
    SubCommand.validateOptions(self)
  File "/cvmfs/cms.cern.ch/crab3/slc6_amd64_gcc493/cms/crabclient/3.3.1910.patch2/lib/python2.7/site-packages/CRABClient/Commands/SubCommand.py", line 580, in validateOptions
    raise ConfigurationException(msg)
ConfigurationException: [91mError[0m: crab_2018_MC is not a valid CRAB project directory.
